<?xml version="1.0"?>
<sdf version="1.7">
  <model name="dual_disk_model">
    <!-- Disk 1 -->
    <link name="disk_1">
      <inertial>
        <mass>5.0</mass>
        <inertia>
          <ixx>0.5</ixx>
          <iyy>0.5</iyy>
          <izz>0.5</izz>
        </inertia>
      </inertial>
      <visual name="disk_1_visual">
        <geometry>
          <cylinder>
            <radius>5</radius>
            <length>0.1</length>
          </cylinder>
        </geometry>
        <material>
          <diffuse>0.5 0.5 0.5 1.0</diffuse>
        </material>
      </visual>
      <collision name="disk_1_collision">
        <geometry>
          <cylinder>
            <radius>5</radius>
            <length>0.1</length>
          </cylinder>
        </geometry>
      </collision>
    </link>

    <!-- Frame for Disk 1 Center -->
    <frame name="disk_1_center">
      <pose relative_to="disk_1">0 0 0 0 0 0</pose>
    </frame>

    <!-- Disk 2 -->
    <link name="disk_2">
      <pose>0 0 0.2 0 0 0</pose>
      <inertial>
        <mass>5.0</mass>
        <inertia>
          <ixx>0.5</ixx>
          <iyy>0.5</iyy>
          <izz>0.5</izz>
        </inertia>
      </inertial>
      <visual name="disk_2_visual">
        <geometry>
          <cylinder>
            <radius>5</radius>
            <length>0.1</length>
          </cylinder>
        </geometry>
        <material>
          <diffuse>0.5 0.5 0.5 1.0</diffuse>
        </material>
      </visual>
      <collision name="disk_2_collision">
        <geometry>
          <cylinder>
            <radius>5</radius>
            <length>0.1</length>
          </cylinder>
        </geometry>
      </collision>
    </link>

    <!-- Frame for Disk 2 Center -->
    <frame name="disk_2_center">
      <pose relative_to="disk_2">0 0 0 0 0 0</pose>
    </frame>

    <!-- Revolute joint between disk_1 and disk_2 -->
    <joint name="disk_joint" type="revolute">
      <parent>disk_1</parent>
      <child>disk_2</child>
      <axis>
        <xyz>0 0 1</xyz>
        <limit>
          <lower>-1e16</lower>
          <upper>1e16</upper>
        </limit>
      </axis>
    </joint>
  </model>
</sdf>


